Workbook

Sheet README
A1: RainReady (working name): Team Task Tracker
A2: Sime Darby Property University Hackathon 2026 | Planet: Climate resilience | Site: Bandar Bukit Raja sub-catchment
B4: Purpose
B5: One place for every task, owner, hand-off, assumption and open item. Update the Status column on 'Task List'; the Summary and Timeline update automatically.
B7: Settings (yellow cells are inputs)
B8: Day 1 date | C8: 46305 | D8: Change this if you start on another day. Timeline dates follow it.
B9: Submission deadline | C9: 46318 | D9: Proposal due 11:59 p.m. (from the competition briefing).
B10: Days remaining | C10: =C9-TODAY() | D10: Calculated.
B11: Project day today | C11: =TODAY()-C8+1 | D11: Calculated. Day 1 = the Day 1 date above.
B13: Team and leads (yellow = enter names)
B14: Role | C14: Lead (name) | D14: Focus
B15: Architecture | D15: 3D modelling: site model, pond and wetland geometry, scenario visuals, web-ready 3D assets, visual style
B16: Mechanical | D16: Analysis and hydrology: MSMA 2 inputs, storage required, pond what-if, sensitivity, assumption ledger
B17: EE-1 Data/GIS | D17: Elevation, land cover and footprint data; catchment and low-lying zones; layer package; elevation-agreement check
B18: EE-2 Dashboard | D18: Four-screen dashboard, formula implementation, advisory prototype, 3D viewer embed, demo and video
B19: EE-3 Evidence & Pitch | D19: Survey, flood-spot back-test, responsibility map, sources and licences, business case, deck text
B20: Whole team | D20: Shared set-up, check-ins, go/no-go gate, submission and link testing
B22: How to use
B23: 1. Enter names in the Team table above and in the Owner column of 'Task List'.
B24: 2. Set each task's Status using the dropdown: Not started, In progress, Blocked, Done.
B25: 3. 'Summary' shows progress by role; 'Timeline' shows the Gantt view; 'Hand-offs' lists what moves between people.
B26: 4. Any new assumed number goes into 'Assumption Ledger'. Take volumes only from the Mechanical lead's table.
B27: 5. Add new tasks by inserting rows inside the table on 'Task List' (Summary covers rows 5 to 100).
B29: Rules to protect credibility
B30: - 3D and map visuals show risk bands or scenarios, never predicted flood depths (terrain error is about 1 m).
B31: - Alerts are advisory and built on official warnings. Never call them a forecast.
B32: - Use neutral wording. Show flow paths and capacity gaps, not blame.
B33: - If behind schedule, drop in this order: stretch hydrology model, demo-video 3D visuals, bench sensor demo.
B34: - Items marked [verify] in 'Open Items' must be confirmed before submitting.

Sheet Task List
A1: Task List
A2: Edit Owner, Status and Notes. Phase is calculated from Start day. Day 1 date is set on README.
A4: ID | B4: Role | C4: Workstream | D4: Task | E4: Deliverable | F4: Priority | G4: Phase | H4: Start day | I4: End day | J4: Depends on | K4: Receives from | L4: Gives to | M4: Owner (name) | N4: Status | O4: Notes
A5: G1 | B5: Whole team | C5: Set-up | D5: Set up shared folder, layer naming, units and coordinate system | E5: One-page data contract | F5: Core | G5: =IF(H5<=3,"P1 Set-up",IF(H5<=7,"P2 Build",IF(H5<=10,"P3 Integrate","P4 Package"))) | H5: 1 | I5: 1 | L5: All | N5: Not started
A6: G2 | B6: Whole team | C6: Set-up | D6: Agree study-area boundary; label SDP land, other developers' land and council areas | E6: Boundary map and note | F6: Core | G6: =IF(H6<=3,"P1 Set-up",IF(H6<=7,"P2 Build",IF(H6<=10,"P3 Integrate","P4 Package"))) | H6: 1 | I6: 2 | K6: Public SDP maps and press | L6: All | N6: Not started
A7: G3 | B7: Whole team | C7: Coordination | D7: Daily 10-minute check-in | E7: Notes in shared folder | F7: Core | G7: =IF(H7<=3,"P1 Set-up",IF(H7<=7,"P2 Build",IF(H7<=10,"P3 Integrate","P4 Package"))) | H7: 1 | I7: 13 | L7: All | N7: Not started
A8: G4 | B8: Whole team | C8: Coordination | D8: Go/no-go gate: layers load and catchment looks plausible | E8: Decision recorded | F8: Core | G8: =IF(H8<=3,"P1 Set-up",IF(H8<=7,"P2 Build",IF(H8<=10,"P3 Integrate","P4 Package"))) | H8: 3 | I8: 3 | J8: D3, D6, A1 | L8: All | N8: Not started
A9: G5 | B9: Whole team | C9: Submission | D9: Compile submission package: deck (max 10 main slides), 5-minute video link, prototype link, supporting docs | E9: Complete package | F9: Core | G9: =IF(H9<=3,"P1 Set-up",IF(H9<=7,"P2 Build",IF(H9<=10,"P3 Integrate","P4 Package"))) | H9: 12 | I9: 13 | J9: S8, W8 | L9: Judges | N9: Not started
A10: G6 | B10: Whole team | C10: Submission | D10: Test every link signed-out or in incognito; proofread | E10: Checklist ticked | F10: Core | G10: =IF(H10<=3,"P1 Set-up",IF(H10<=7,"P2 Build",IF(H10<=10,"P3 Integrate","P4 Package"))) | H10: 13 | I10: 13 | J10: G5 | L10: Judges | N10: Not started
A11: D1 | B11: EE-1 Data/GIS | C11: Data | D11: Download elevation models (FABDEM plus a second model for comparison); check licence terms | E11: Raster files and licence note | F11: Core | G11: =IF(H11<=3,"P1 Set-up",IF(H11<=7,"P2 Build",IF(H11<=10,"P3 Integrate","P4 Package"))) | H11: 1 | I11: 2 | J11: G1 | L11: D3, A1 | N11: Not started
A12: D2 | B12: EE-1 Data/GIS | C12: Data | D12: Download land cover, building footprints and roads | E12: Layer files | F12: Core | G12: =IF(H12<=3,"P1 Set-up",IF(H12<=7,"P2 Build",IF(H12<=10,"P3 Integrate","P4 Package"))) | H12: 1 | I12: 2 | J12: G1 | L12: D3, A1, M2 | N12: Not started
A13: D3 | B13: EE-1 Data/GIS | C13: Analysis | D13: Delineate catchment and flow paths using the Mechanical lead's parameters | E13: Catchment polygon and flow lines | F13: Core | G13: =IF(H13<=3,"P1 Set-up",IF(H13<=7,"P2 Build",IF(H13<=10,"P3 Integrate","P4 Package"))) | H13: 2 | I13: 4 | J13: D1, D2, M2 | K13: Mechanical (parameters) | L13: M1, A5 | N13: Not started
A14: D4 | B14: EE-1 Data/GIS | C14: Analysis | D14: Map low-lying zones and risk bands | E14: Risk-band layer | F14: Core | G14: =IF(H14<=3,"P1 Set-up",IF(H14<=7,"P2 Build",IF(H14<=10,"P3 Integrate","P4 Package"))) | H14: 3 | I14: 4 | J14: D3 | L14: S4, W2, A4 | N14: Not started
A15: D5 | B15: EE-1 Data/GIS | C15: Validation | D15: Elevation-agreement check: which high-risk cells hold across two terrain models | E15: Robust-hotspot layer and note | F15: Core | G15: =IF(H15<=3,"P1 Set-up",IF(H15<=7,"P2 Build",IF(H15<=10,"P3 Integrate","P4 Package"))) | H15: 4 | I15: 5 | J15: D4 | L15: W2, S8 | N15: Not started
A16: D6 | B16: EE-1 Data/GIS | C16: Data | D16: Deliver clean layer package v1 (naming, units, coordinate system) | E16: Layer package | F16: Core | G16: =IF(H16<=3,"P1 Set-up",IF(H16<=7,"P2 Build",IF(H16<=10,"P3 Integrate","P4 Package"))) | H16: 2 | I16: 3 | J16: D1, D2, G1 | L16: A1, M1, M2 | N16: Not started
A17: A8 | B17: Architecture | C17: 3D modelling | D17: Visual style sheet: colours for risk bands, ownership, flow paths (accessible) | E17: One-page style sheet | F17: Core | G17: =IF(H17<=3,"P1 Set-up",IF(H17<=7,"P2 Build",IF(H17<=10,"P3 Integrate","P4 Package"))) | H17: 1 | I17: 2 | L17: W1, S8 | N17: Not started
A18: A1 | B18: Architecture | C18: 3D modelling | D18: Base 3D site model: terrain, buildings, roads, Townpark and ponds | E18: Model file plus GLB export | F18: Core | G18: =IF(H18<=3,"P1 Set-up",IF(H18<=7,"P2 Build",IF(H18<=10,"P3 Integrate","P4 Package"))) | H18: 1 | I18: 4 | J18: D1, D2, D6 | K18: EE-1 (terrain, footprints) | L18: A2, A5, W6 | N18: Not started
A19: A2 | B19: Architecture | C19: 3D modelling | D19: Parametric pond and wetland objects (area and depth adjustable); Townpark from SDP booklet; Taman Mutiara pond | E19: Pond objects | F19: Core | G19: =IF(H19<=3,"P1 Set-up",IF(H19<=7,"P2 Build",IF(H19<=10,"P3 Integrate","P4 Package"))) | H19: 3 | I19: 5 | J19: A1 | K19: Mechanical (inputs) | L19: A3, A4 | N19: Not started
A20: A3 | B20: Architecture | C20: Design options | D20: Blue-green option library: deeper pond, extra pond, wetland, swale, bioretention, dual-use park | E20: Options catalogue with area, depth, volume | F20: Core | G20: =IF(H20<=3,"P1 Set-up",IF(H20<=7,"P2 Build",IF(H20<=10,"P3 Integrate","P4 Package"))) | H20: 4 | I20: 6 | J20: A2, M4 | K20: Mechanical (volumes) | L20: W3, S8 | N20: Not started
A21: A5 | B21: Architecture | C21: 3D modelling | D21: Flow-path scene: Setia Alam to BBR route and council boundaries | E21: Annotated scene | F21: Core | G21: =IF(H21<=3,"P1 Set-up",IF(H21<=7,"P2 Build",IF(H21<=10,"P3 Integrate","P4 Package"))) | H21: 5 | I21: 6 | J21: A1, D3 | K21: EE-1 (flow lines) | L21: W6, S8 | N21: Not started
A22: A4 | B22: Architecture | C22: 3D modelling | D22: Scenario views: existing versus added storage, with risk bands (labelled illustrative) | E22: 3-4 rendered scenes | F22: Core | G22: =IF(H22<=3,"P1 Set-up",IF(H22<=7,"P2 Build",IF(H22<=10,"P3 Integrate","P4 Package"))) | H22: 6 | I22: 8 | J22: A2, A3, D4 | K22: Mechanical (storage gap) | L22: S8, W6 | N22: Not started
A23: A6 | B23: Architecture | C23: 3D modelling | D23: Optimise web assets (small files, clear layer names) | E23: GLB files and layer list | F23: Core | G23: =IF(H23<=3,"P1 Set-up",IF(H23<=7,"P2 Build",IF(H23<=10,"P3 Integrate","P4 Package"))) | H23: 6 | I23: 8 | J23: A1, A2 | L23: W6 | N23: Not started
A24: A7 | B24: Architecture | C24: 3D modelling | D24: Flythrough or storyboard for the 5-minute video | E24: Clip or storyboard | F24: Stretch | G24: =IF(H24<=3,"P1 Set-up",IF(H24<=7,"P2 Build",IF(H24<=10,"P3 Integrate","P4 Package"))) | H24: 9 | I24: 11 | J24: A4, A6 | L24: W8 | N24: Not started
A25: M2 | B25: Mechanical | C25: Hydrology | D25: Design inputs from MSMA 2: rainfall intensity for design storm, runoff coefficients, time of concentration (note outdated curves) | E25: Parameter table with sources | F25: Core | G25: =IF(H25<=3,"P1 Set-up",IF(H25<=7,"P2 Build",IF(H25<=10,"P3 Integrate","P4 Package"))) | H25: 1 | I25: 3 | J25: D2 | L25: D3, M3 | N25: Not started
A26: M8 | B26: Mechanical | C26: Governance | D26: Maintain the assumption ledger | E26: Assumption Ledger sheet | F26: Core | G26: =IF(H26<=3,"P1 Set-up",IF(H26<=7,"P2 Build",IF(H26<=10,"P3 Integrate","P4 Package"))) | H26: 1 | I26: 13 | K26: All | L26: All | N26: Not started
A27: M1 | B27: Mechanical | C27: Hydrology | D27: Review catchment: area, slope, flow paths; confirm the Setia Alam contribution is plausible | E27: Approved catchment and note | F27: Core | G27: =IF(H27<=3,"P1 Set-up",IF(H27<=7,"P2 Build",IF(H27<=10,"P3 Integrate","P4 Package"))) | H27: 3 | I27: 4 | J27: D3, D6 | K27: EE-1 (catchment) | L27: M3 | N27: Not started
A28: M3 | B28: Mechanical | C28: Hydrology | D28: Compute storage required for the design storm as low, central and high values | E28: Storage-required table | F28: Core | G28: =IF(H28<=3,"P1 Set-up",IF(H28<=7,"P2 Build",IF(H28<=10,"P3 Integrate","P4 Package"))) | H28: 3 | I28: 5 | J28: M1, M2 | L28: M4, M5, A3 | N28: Not started
A29: M4 | B29: Mechanical | C29: Hydrology | D29: Pond what-if engine: volume balance for given area and depth (optionally routed) | E29: Validated formulas and test cases | F29: Core | G29: =IF(H29<=3,"P1 Set-up",IF(H29<=7,"P2 Build",IF(H29<=10,"P3 Integrate","P4 Package"))) | H29: 4 | I29: 6 | J29: M3 | L29: W3, A3 | N29: Not started
A30: M5 | B30: Mechanical | C30: Hydrology | D30: Reconcile existing storage (Townpark 16,000 / 34,000 / 50,000 m3; Taman Mutiara about 2 ha) against requirement | E30: Storage-gap table with ranges | F30: Core | G30: =IF(H30<=3,"P1 Set-up",IF(H30<=7,"P2 Build",IF(H30<=10,"P3 Integrate","P4 Package"))) | H30: 5 | I30: 6 | J30: M3, M4 | L30: A4, S8 | N30: Not started
A31: M6 | B31: Mechanical | C31: Analysis | D31: Sensitivity analysis: rainfall, runoff, pond depth, terrain error | E31: One-page chart and table | F31: Core | G31: =IF(H31<=3,"P1 Set-up",IF(H31<=7,"P2 Build",IF(H31<=10,"P3 Integrate","P4 Package"))) | H31: 7 | I31: 8 | J31: M5 | L31: S8 | N31: Not started
A32: M7 | B32: Mechanical | C32: Validation | D32: Plausibility back-test against documented floods (Dec 2021, Jun 2023, Apr 2024); report honestly, do not tune | E32: Short note | F32: Core | G32: =IF(H32<=3,"P1 Set-up",IF(H32<=7,"P2 Build",IF(H32<=10,"P3 Integrate","P4 Package"))) | H32: 7 | I32: 8 | J32: M5, S3 | K32: EE-3 (flood spots) | L32: S4, S8 | N32: Not started
A33: M9 | B33: Mechanical | C33: Hydrology | D33: Stretch: simple rainfall-runoff model of the sub-catchment (e.g. HEC-HMS) | E33: Run and notes | F33: Stretch | G33: =IF(H33<=3,"P1 Set-up",IF(H33<=7,"P2 Build",IF(H33<=10,"P3 Integrate","P4 Package"))) | H33: 8 | I33: 10 | J33: M5 | L33: S8 | N33: Not started
A34: W1 | B34: EE-2 Dashboard | C34: Dashboard | D34: Dashboard skeleton and layout using the style sheet | E34: Working shell | F34: Core | G34: =IF(H34<=3,"P1 Set-up",IF(H34<=7,"P2 Build",IF(H34<=10,"P3 Integrate","P4 Package"))) | H34: 3 | I34: 4 | J34: A8 | K34: Architecture (style) | L34: W2 | N34: Not started
A35: W2 | B35: EE-2 Dashboard | C35: Dashboard | D35: Screen 1: catchment map with flood-spot overlay and robust-hotspot layer | E35: Screen 1 | F35: Core | G35: =IF(H35<=3,"P1 Set-up",IF(H35<=7,"P2 Build",IF(H35<=10,"P3 Integrate","P4 Package"))) | H35: 5 | I35: 6 | J35: W1, D4, D5, S3 | K35: EE-1 (layers) | L35: W7 | N35: Not started
A36: W3 | B36: EE-2 Dashboard | C36: Dashboard | D36: Screen 2: pond what-if with sliders; implement Mechanical formulas | E36: Screen 2 | F36: Core | G36: =IF(H36<=3,"P1 Set-up",IF(H36<=7,"P2 Build",IF(H36<=10,"P3 Integrate","P4 Package"))) | H36: 6 | I36: 8 | J36: M4, A3, W1 | K36: Mechanical (formulas) | L36: W7 | N36: Not started
A37: W4 | B37: EE-2 Dashboard | C37: Dashboard | D37: Screen 3: responsibility panel (agency, contact, confidence label) | E37: Screen 3 | F37: Core | G37: =IF(H37<=3,"P1 Set-up",IF(H37<=7,"P2 Build",IF(H37<=10,"P3 Integrate","P4 Package"))) | H37: 6 | I37: 7 | J37: S5, W1 | K37: EE-3 (template) | L37: W8 | N37: Not started
A38: W5 | B38: EE-2 Dashboard | C38: Advisory | D38: Screen 4: advisory prototype from official MET Malaysia warnings; label 'advisory, not a forecast' | E38: Screen 4 | F38: Core | G38: =IF(H38<=3,"P1 Set-up",IF(H38<=7,"P2 Build",IF(H38<=10,"P3 Integrate","P4 Package"))) | H38: 7 | I38: 9 | J38: W1 | L38: W8 | N38: Not started
A39: W6 | B39: EE-2 Dashboard | C39: Dashboard | D39: Embed the 3D viewer (GLB models) | E39: Working 3D view | F39: Core | G39: =IF(H39<=3,"P1 Set-up",IF(H39<=7,"P2 Build",IF(H39<=10,"P3 Integrate","P4 Package"))) | H39: 8 | I39: 9 | J39: A6, A5, A4 | K39: Architecture (GLB) | L39: W8 | N39: Not started
A40: W7 | B40: EE-2 Dashboard | C40: Validation | D40: Verify dashboard formulas against hand calculations | E40: Test log | F40: Core | G40: =IF(H40<=3,"P1 Set-up",IF(H40<=7,"P2 Build",IF(H40<=10,"P3 Integrate","P4 Package"))) | H40: 8 | I40: 9 | J40: W3, M4 | K40: Mechanical (test cases) | L40: W8 | N40: Not started
A41: W8 | B41: EE-2 Dashboard | C41: Demo | D41: Package the demo and record the 5-minute video | E41: Video link and demo build | F41: Core | G41: =IF(H41<=3,"P1 Set-up",IF(H41<=7,"P2 Build",IF(H41<=10,"P3 Integrate","P4 Package"))) | H41: 10 | I41: 12 | J41: W2-W7, A7 | L41: G5 | N41: Not started
...

Sheet Summary
A1: Progress Summary
A2: All figures are formulas driven by the Status column on 'Task List'.
A4: Role | B4: Lead | C4: Not started | D4: In progress | E4: Blocked | F4: Done | G4: Total | H4: % Done
A5: Architecture | B5: =IFERROR(INDEX(README!$C$15:$C$20,MATCH($A5,README!$B$15:$B$20,0))&"","") | C5: =COUNTIFS('Task List'!$B$5:$B$100,$A5,'Task List'!$N$5:$N$100,"Not started") | D5: =COUNTIFS('Task List'!$B$5:$B$100,$A5,'Task List'!$N$5:$N$100,"In progress") | E5: =COUNTIFS('Task List'!$B$5:$B$100,$A5,'Task List'!$N$5:$N$100,"Blocked") | F5: =COUNTIFS('Task List'!$B$5:$B$100,$A5,'Task List'!$N$5:$N$100,"Done") | G5: =SUM(C5:F5) | H5: =IF(G5=0,0,F5/G5)
A6: Mechanical | B6: =IFERROR(INDEX(README!$C$15:$C$20,MATCH($A6,README!$B$15:$B$20,0))&"","") | C6: =COUNTIFS('Task List'!$B$5:$B$100,$A6,'Task List'!$N$5:$N$100,"Not started") | D6: =COUNTIFS('Task List'!$B$5:$B$100,$A6,'Task List'!$N$5:$N$100,"In progress") | E6: =COUNTIFS('Task List'!$B$5:$B$100,$A6,'Task List'!$N$5:$N$100,"Blocked") | F6: =COUNTIFS('Task List'!$B$5:$B$100,$A6,'Task List'!$N$5:$N$100,"Done") | G6: =SUM(C6:F6) | H6: =IF(G6=0,0,F6/G6)
A7: EE-1 Data/GIS | B7: =IFERROR(INDEX(README!$C$15:$C$20,MATCH($A7,README!$B$15:$B$20,0))&"","") | C7: =COUNTIFS('Task List'!$B$5:$B$100,$A7,'Task List'!$N$5:$N$100,"Not started") | D7: =COUNTIFS('Task List'!$B$5:$B$100,$A7,'Task List'!$N$5:$N$100,"In progress") | E7: =COUNTIFS('Task List'!$B$5:$B$100,$A7,'Task List'!$N$5:$N$100,"Blocked") | F7: =COUNTIFS('Task List'!$B$5:$B$100,$A7,'Task List'!$N$5:$N$100,"Done") | G7: =SUM(C7:F7) | H7: =IF(G7=0,0,F7/G7)
A8: EE-2 Dashboard | B8: =IFERROR(INDEX(README!$C$15:$C$20,MATCH($A8,README!$B$15:$B$20,0))&"","") | C8: =COUNTIFS('Task List'!$B$5:$B$100,$A8,'Task List'!$N$5:$N$100,"Not started") | D8: =COUNTIFS('Task List'!$B$5:$B$100,$A8,'Task List'!$N$5:$N$100,"In progress") | E8: =COUNTIFS('Task List'!$B$5:$B$100,$A8,'Task List'!$N$5:$N$100,"Blocked") | F8: =COUNTIFS('Task List'!$B$5:$B$100,$A8,'Task List'!$N$5:$N$100,"Done") | G8: =SUM(C8:F8) | H8: =IF(G8=0,0,F8/G8)
A9: EE-3 Evidence & Pitch | B9: =IFERROR(INDEX(README!$C$15:$C$20,MATCH($A9,README!$B$15:$B$20,0))&"","") | C9: =COUNTIFS('Task List'!$B$5:$B$100,$A9,'Task List'!$N$5:$N$100,"Not started") | D9: =COUNTIFS('Task List'!$B$5:$B$100,$A9,'Task List'!$N$5:$N$100,"In progress") | E9: =COUNTIFS('Task List'!$B$5:$B$100,$A9,'Task List'!$N$5:$N$100,"Blocked") | F9: =COUNTIFS('Task List'!$B$5:$B$100,$A9,'Task List'!$N$5:$N$100,"Done") | G9: =SUM(C9:F9) | H9: =IF(G9=0,0,F9/G9)
A10: Whole team | B10: =IFERROR(INDEX(README!$C$15:$C$20,MATCH($A10,README!$B$15:$B$20,0))&"","") | C10: =COUNTIFS('Task List'!$B$5:$B$100,$A10,'Task List'!$N$5:$N$100,"Not started") | D10: =COUNTIFS('Task List'!$B$5:$B$100,$A10,'Task List'!$N$5:$N$100,"In progress") | E10: =COUNTIFS('Task List'!$B$5:$B$100,$A10,'Task List'!$N$5:$N$100,"Blocked") | F10: =COUNTIFS('Task List'!$B$5:$B$100,$A10,'Task List'!$N$5:$N$100,"Done") | G10: =SUM(C10:F10) | H10: =IF(G10=0,0,F10/G10)
A11: Total | C11: =SUM(C5:C10) | D11: =SUM(D5:D10) | E11: =SUM(E5:E10) | F11: =SUM(F5:F10) | G11: =SUM(G5:G10) | H11: =IF(G11=0,0,F11/G11)
A14: By priority
A15: Priority | C15: Not started | D15: In progress | E15: Blocked | F15: Done | G15: Total | H15: % Done
A16: Core | C16: =COUNTIFS('Task List'!$F$5:$F$100,$A16,'Task List'!$N$5:$N$100,"Not started") | D16: =COUNTIFS('Task List'!$F$5:$F$100,$A16,'Task List'!$N$5:$N$100,"In progress") | E16: =COUNTIFS('Task List'!$F$5:$F$100,$A16,'Task List'!$N$5:$N$100,"Blocked") | F16: =COUNTIFS('Task List'!$F$5:$F$100,$A16,'Task List'!$N$5:$N$100,"Done") | G16: =SUM(C16:F16) | H16: =IF(G16=0,0,F16/G16)
A17: Stretch | C17: =COUNTIFS('Task List'!$F$5:$F$100,$A17,'Task List'!$N$5:$N$100,"Not started") | D17: =COUNTIFS('Task List'!$F$5:$F$100,$A17,'Task List'!$N$5:$N$100,"In progress") | E17: =COUNTIFS('Task List'!$F$5:$F$100,$A17,'Task List'!$N$5:$N$100,"Blocked") | F17: =COUNTIFS('Task List'!$F$5:$F$100,$A17,'Task List'!$N$5:$N$100,"Done") | G17: =SUM(C17:F17) | H17: =IF(G17=0,0,F17/G17)
A18: Optional | C18: =COUNTIFS('Task List'!$F$5:$F$100,$A18,'Task List'!$N$5:$N$100,"Not started") | D18: =COUNTIFS('Task List'!$F$5:$F$100,$A18,'Task List'!$N$5:$N$100,"In progress") | E18: =COUNTIFS('Task List'!$F$5:$F$100,$A18,'Task List'!$N$5:$N$100,"Blocked") | F18: =COUNTIFS('Task List'!$F$5:$F$100,$A18,'Task List'!$N$5:$N$100,"Done") | G18: =SUM(C18:F18) | H18: =IF(G18=0,0,F18/G18)
A21: Schedule
A22: Days remaining to deadline | C22: =README!C10
A23: Project day today | C23: =README!C11
A24: Core tasks due by today and not done | C24: =COUNTIFS('Task List'!$F$5:$F$100,"Core",'Task List'!$I$5:$I$100,"<="&README!C11,'Task List'!$N$5:$N$100,"<>Done")

Sheet Timeline
A1: Timeline (Gantt)
A2: Bars follow Start and End day on 'Task List'. Teal = Core, amber = Stretch/Optional. The current project day is outlined.
F4: Day | G4: 1 | H4: 2 | I4: 3 | J4: 4 | K4: 5 | L4: 6 | M4: 7 | N4: 8 | O4: 9 | P4: 10 | Q4: 11 | R4: 12 | S4: 13
A5: ID | B5: Role | C5: Task | D5: Priority | E5: Start | F5: End | G5: =README!$C$8+1-1 | H5: =README!$C$8+2-1 | I5: =README!$C$8+3-1 | J5: =README!$C$8+4-1 | K5: =README!$C$8+5-1 | L5: =README!$C$8+6-1 | M5: =README!$C$8+7-1 | N5: =README!$C$8+8-1 | O5: =README!$C$8+9-1 | P5: =README!$C$8+10-1 | Q5: =README!$C$8+11-1 | R5: =README!$C$8+12-1 | S5: =README!$C$8+13-1
A6: ='Task List'!A5 | B6: ='Task List'!B5 | C6: ='Task List'!D5 | D6: ='Task List'!F5 | E6: ='Task List'!H5 | F6: ='Task List'!I5 | G6: =IF(AND(G$4>=$E6,G$4<=$F6),1,0) | H6: =IF(AND(H$4>=$E6,H$4<=$F6),1,0) | I6: =IF(AND(I$4>=$E6,I$4<=$F6),1,0) | J6: =IF(AND(J$4>=$E6,J$4<=$F6),1,0) | K6: =IF(AND(K$4>=$E6,K$4<=$F6),1,0) | L6: =IF(AND(L$4>=$E6,L$4<=$F6),1,0) | M6: =IF(AND(M$4>=$E6,M$4<=$F6),1,0) | N6: =IF(AND(N$4>=$E6,N$4<=$F6),1,0) | ... S6: =IF(AND(S$4>=$E6,S$4<=$F6),1,0)
A7: ='Task List'!A6 | B7: ='Task List'!B6 | C7: ='Task List'!D6 | D7: ='Task List'!F6 | E7: ='Task List'!H6 | F7: ='Task List'!I6 | G7: =IF(AND(G$4>=$E7,G$4<=$F7),1,0) | H7: =IF(AND(H$4>=$E7,H$4<=$F7),1,0) | I7: =IF(AND(I$4>=$E7,I$4<=$F7),1,0) | J7: =IF(AND(J$4>=$E7,J$4<=$F7),1,0) | K7: =IF(AND(K$4>=$E7,K$4<=$F7),1,0) | L7: =IF(AND(L$4>=$E7,L$4<=$F7),1,0) | M7: =IF(AND(M$4>=$E7,M$4<=$F7),1,0) | N7: =IF(AND(N$4>=$E7,N$4<=$F7),1,0) | ... S7: =IF(AND(S$4>=$E7,S$4<=$F7),1,0)
A8: ='Task List'!A7 | B8: ='Task List'!B7 | C8: ='Task List'!D7 | D8: ='Task List'!F7 | E8: ='Task List'!H7 | F8: ='Task List'!I7 | G8: =IF(AND(G$4>=$E8,G$4<=$F8),1,0) | H8: =IF(AND(H$4>=$E8,H$4<=$F8),1,0) | I8: =IF(AND(I$4>=$E8,I$4<=$F8),1,0) | J8: =IF(AND(J$4>=$E8,J$4<=$F8),1,0) | K8: =IF(AND(K$4>=$E8,K$4<=$F8),1,0) | L8: =IF(AND(L$4>=$E8,L$4<=$F8),1,0) | M8: =IF(AND(M$4>=$E8,M$4<=$F8),1,0) | N8: =IF(AND(N$4>=$E8,N$4<=$F8),1,0) | ... S8: =IF(AND(S$4>=$E8,S$4<=$F8),1,0)
A9: ='Task List'!A8 | B9: ='Task List'!B8 | C9: ='Task List'!D8 | D9: ='Task List'!F8 | E9: ='Task List'!H8 | F9: ='Task List'!I8 | G9: =IF(AND(G$4>=$E9,G$4<=$F9),1,0) | H9: =IF(AND(H$4>=$E9,H$4<=$F9),1,0) | I9: =IF(AND(I$4>=$E9,I$4<=$F9),1,0) | J9: =IF(AND(J$4>=$E9,J$4<=$F9),1,0) | K9: =IF(AND(K$4>=$E9,K$4<=$F9),1,0) | L9: =IF(AND(L$4>=$E9,L$4<=$F9),1,0) | M9: =IF(AND(M$4>=$E9,M$4<=$F9),1,0) | N9: =IF(AND(N$4>=$E9,N$4<=$F9),1,0) | ... S9: =IF(AND(S$4>=$E9,S$4<=$F9),1,0)
A10: ='Task List'!A9 | B10: ='Task List'!B9 | C10: ='Task List'!D9 | D10: ='Task List'!F9 | E10: ='Task List'!H9 | F10: ='Task List'!I9 | G10: =IF(AND(G$4>=$E10,G$4<=$F10),1,0) | H10: =IF(AND(H$4>=$E10,H$4<=$F10),1,0) | I10: =IF(AND(I$4>=$E10,I$4<=$F10),1,0) | J10: =IF(AND(J$4>=$E10,J$4<=$F10),1,0) | K10: =IF(AND(K$4>=$E10,K$4<=$F10),1,0) | L10: =IF(AND(L$4>=$E10,L$4<=$F10),1,0) | M10: =IF(AND(M$4>=$E10,M$4<=$F10),1,0) | N10: =IF(AND(N$4>=$E10,N$4<=$F10),1,0) | ... S10: =IF(AND(S$4>=$E10,S$4<=$F10),1,0)
A11: ='Task List'!A10 | B11: ='Task List'!B10 | C11: ='Task List'!D10 | D11: ='Task List'!F10 | E11: ='Task List'!H10 | F11: ='Task List'!I10 | G11: =IF(AND(G$4>=$E11,G$4<=$F11),1,0) | H11: =IF(AND(H$4>=$E11,H$4<=$F11),1,0) | I11: =IF(AND(I$4>=$E11,I$4<=$F11),1,0) | J11: =IF(AND(J$4>=$E11,J$4<=$F11),1,0) | K11: =IF(AND(K$4>=$E11,K$4<=$F11),1,0) | L11: =IF(AND(L$4>=$E11,L$4<=$F11),1,0) | M11: =IF(AND(M$4>=$E11,M$4<=$F11),1,0) | N11: =IF(AND(N$4>=$E11,N$4<=$F11),1,0) | ... S11: =IF(AND(S$4>=$E11,S$4<=$F11),1,0)
A12: ='Task List'!A11 | B12: ='Task List'!B11 | C12: ='Task List'!D11 | D12: ='Task List'!F11 | E12: ='Task List'!H11 | F12: ='Task List'!I11 | G12: =IF(AND(G$4>=$E12,G$4<=$F12),1,0) | H12: =IF(AND(H$4>=$E12,H$4<=$F12),1,0) | I12: =IF(AND(I$4>=$E12,I$4<=$F12),1,0) | J12: =IF(AND(J$4>=$E12,J$4<=$F12),1,0) | K12: =IF(AND(K$4>=$E12,K$4<=$F12),1,0) | L12: =IF(AND(L$4>=$E12,L$4<=$F12),1,0) | M12: =IF(AND(M$4>=$E12,M$4<=$F12),1,0) | N12: =IF(AND(N$4>=$E12,N$4<=$F12),1,0) | ... S12: =IF(AND(S$4>=$E12,S$4<=$F12),1,0)
A13: ='Task List'!A12 | B13: ='Task List'!B12 | C13: ='Task List'!D12 | D13: ='Task List'!F12 | E13: ='Task List'!H12 | F13: ='Task List'!I12 | G13: =IF(AND(G$4>=$E13,G$4<=$F13),1,0) | H13: =IF(AND(H$4>=$E13,H$4<=$F13),1,0) | I13: =IF(AND(I$4>=$E13,I$4<=$F13),1,0) | J13: =IF(AND(J$4>=$E13,J$4<=$F13),1,0) | K13: =IF(AND(K$4>=$E13,K$4<=$F13),1,0) | L13: =IF(AND(L$4>=$E13,L$4<=$F13),1,0) | M13: =IF(AND(M$4>=$E13,M$4<=$F13),1,0) | N13: =IF(AND(N$4>=$E13,N$4<=$F13),1,0) | ... S13: =IF(AND(S$4>=$E13,S$4<=$F13),1,0)
A14: ='Task List'!A13 | B14: ='Task List'!B13 | C14: ='Task List'!D13 | D14: ='Task List'!F13 | E14: ='Task List'!H13 | F14: ='Task List'!I13 | G14: =IF(AND(G$4>=$E14,G$4<=$F14),1,0) | H14: =IF(AND(H$4>=$E14,H$4<=$F14),1,0) | I14: =IF(AND(I$4>=$E14,I$4<=$F14),1,0) | J14: =IF(AND(J$4>=$E14,J$4<=$F14),1,0) | K14: =IF(AND(K$4>=$E14,K$4<=$F14),1,0) | L14: =IF(AND(L$4>=$E14,L$4<=$F14),1,0) | M14: =IF(AND(M$4>=$E14,M$4<=$F14),1,0) | N14: =IF(AND(N$4>=$E14,N$4<=$F14),1,0) | ... S14: =IF(AND(S$4>=$E14,S$4<=$F14),1,0)
A15: ='Task List'!A14 | B15: ='Task List'!B14 | C15: ='Task List'!D14 | D15: ='Task List'!F14 | E15: ='Task List'!H14 | F15: ='Task List'!I14 | G15: =IF(AND(G$4>=$E15,G$4<=$F15),1,0) | H15: =IF(AND(H$4>=$E15,H$4<=$F15),1,0) | I15: =IF(AND(I$4>=$E15,I$4<=$F15),1,0) | J15: =IF(AND(J$4>=$E15,J$4<=$F15),1,0) | K15: =IF(AND(K$4>=$E15,K$4<=$F15),1,0) | L15: =IF(AND(L$4>=$E15,L$4<=$F15),1,0) | M15: =IF(AND(M$4>=$E15,M$4<=$F15),1,0) | N15: =IF(AND(N$4>=$E15,N$4<=$F15),1,0) | ... S15: =IF(AND(S$4>=$E15,S$4<=$F15),1,0)
A16: ='Task List'!A15 | B16: ='Task List'!B15 | C16: ='Task List'!D15 | D16: ='Task List'!F15 | E16: ='Task List'!H15 | F16: ='Task List'!I15 | G16: =IF(AND(G$4>=$E16,G$4<=$F16),1,0) | H16: =IF(AND(H$4>=$E16,H$4<=$F16),1,0) | I16: =IF(AND(I$4>=$E16,I$4<=$F16),1,0) | J16: =IF(AND(J$4>=$E16,J$4<=$F16),1,0) | K16: =IF(AND(K$4>=$E16,K$4<=$F16),1,0) | L16: =IF(AND(L$4>=$E16,L$4<=$F16),1,0) | M16: =IF(AND(M$4>=$E16,M$4<=$F16),1,0) | N16: =IF(AND(N$4>=$E16,N$4<=$F16),1,0) | ... S16: =IF(AND(S$4>=$E16,S$4<=$F16),1,0)
A17: ='Task List'!A16 | B17: ='Task List'!B16 | C17: ='Task List'!D16 | D17: ='Task List'!F16 | E17: ='Task List'!H16 | F17: ='Task List'!I16 | G17: =IF(AND(G$4>=$E17,G$4<=$F17),1,0) | H17: =IF(AND(H$4>=$E17,H$4<=$F17),1,0) | I17: =IF(AND(I$4>=$E17,I$4<=$F17),1,0) | J17: =IF(AND(J$4>=$E17,J$4<=$F17),1,0) | K17: =IF(AND(K$4>=$E17,K$4<=$F17),1,0) | L17: =IF(AND(L$4>=$E17,L$4<=$F17),1,0) | M17: =IF(AND(M$4>=$E17,M$4<=$F17),1,0) | N17: =IF(AND(N$4>=$E17,N$4<=$F17),1,0) | ... S17: =IF(AND(S$4>=$E17,S$4<=$F17),1,0)
... A51: ='Task List'!A50 | B51: ='Task List'!B50 | C51: ='Task List'!D50 | D51: ='Task List'!F50 | E51: ='Task List'!H50 | F51: ='Task List'!I50 | G51: =IF(AND(G$4>=$E51,G$4<=$F51),1,0) | H51: =IF(AND(H$4>=$E51,H$4<=$F51),1,0) | I51: =IF(AND(I$4>=$E51,I$4<=$F51),1,0) | J51: =IF(AND(J$4>=$E51,J$4<=$F51),1,0) | K51: =IF(AND(K$4>=$E51,K$4<=$F51),1,0) | L51: =IF(AND(L$4>=$E51,L$4<=$F51),1,0) | M51: =IF(AND(M$4>=$E51,M$4<=$F51),1,0) | N51: =IF(AND(N$4>=$E51,N$4<=$F51),1,0) | ... S51: =IF(AND(S$4>=$E51,S$4<=$F51),1,0)

Sheet Hand-offs
A1: Hand-offs
A2: What must move between people, in what format, and by when. Delays here block other roles.
A4: # | B4: From | C4: To | D4: What | E4: Format | F4: Needed by (day) | G4: Linked tasks | H4: Received?
A5: 1 | B5: Mechanical | C5: EE-1 Data/GIS | D5: Delineation parameters (thresholds, outlet point) | E5: Short doc | F5: 2 | G5: M2, D3
A6: 2 | B6: EE-1 Data/GIS | C6: Mechanical | D6: Catchment polygon, land cover, elevation models | E6: GeoTIFF / GeoJSON | F6: 3 | G6: D3, D6, M1
A7: 3 | B7: EE-1 Data/GIS | C7: Architecture | D7: Terrain, building footprints, roads | E7: GeoTIFF / OBJ / GeoJSON | F7: 3 | G7: D6, A1
A8: 4 | B8: EE-3 Evidence & Pitch | C8: Mechanical, EE-1 | D8: Documented flood spots with dates and sources | E8: CSV | F8: 3 | G8: S3, M7, D4
A9: 5 | B9: Mechanical | C9: EE-2 Dashboard | D9: Formulas, units and test cases for the what-if | E9: Document and CSV | F9: 5 | G9: M4, W3
A10: 6 | B10: Mechanical | C10: Architecture | D10: Storage volume for each pond option | E10: Table | F10: 5 | G10: M3, A3
A11: 7 | B11: Architecture | C11: EE-2 Dashboard | D11: GLB models, layer list and style sheet | E11: GLB and one-page PDF | F11: 6 | G11: A6, A8, W6
A12: 8 | B12: EE-1 Data/GIS | C12: EE-2 Dashboard | D12: Risk-band and robust-hotspot layers | E12: GeoJSON | F12: 5 | G12: D4, D5, W2
A13: 9 | B13: EE-3 Evidence & Pitch | C13: EE-2 Dashboard | D13: Responsibility-map template and entries | E13: CSV | F13: 6 | G13: S5, W4
A14: 10 | B14: Mechanical | C14: EE-3 Evidence & Pitch | D14: Storage gap, sensitivity chart and ledger for the deck | E14: Table and chart | F14: 8 | G14: M5, M6, S8
A15: 11 | B15: EE-3 Evidence & Pitch | C15: All | D15: Survey results and sources list | E15: Summary doc | F15: 9 | G15: S2, S6
A16: 12 | B16: Architecture | C16: EE-3 Evidence & Pitch | D16: Scenario visuals for the deck | E16: PNG / PDF | F16: 11 | G16: A4, S8
A17: 13 | B17: EE-2 Dashboard | C17: All | D17: Working demo build | E17: Link | F17: 10 | G17: W2-W7

Sheet Assumption Ledger
A1: Assumption Ledger
A2: Every number we did not measure. Owner: Mechanical lead. Replace 'Assumed' and 'Unknown' values when better data arrives.
A4: # | B4: Item | C4: Value or range | D4: Status | E4: Source or basis | F4: Effect if wrong | G4: Replace with | H4: Owner
A5: 1 | B5: Wetland Townpark storage | C5: 16,000 m3 normal; 34,000 m3 additional; 50,000 m3 maximum | D5: Sourced | E5: SDP Bandar Bukit Raja booklet (design figures, not as-built) | F5: Over- or under-states storage | G5: As-built data | H5: Mechanical
A6: 2 | B6: Taman Mutiara pond area | C6: About 2 ha | D6: Sourced | E6: Selangor Journal (undated); confirm date and completion | F6: Same | G6: Council drawings | H6: Mechanical
A7: 3 | B7: Taman Mutiara pond depth and status | C7: [TBD] m; completion unconfirmed | D7: Unknown | E7: Utusan Nov 2024: 25% built, delayed by pump-capacity issues | F7: Storage mis-estimated | G7: Council or JPS data | H7: Mechanical
A8: 4 | B8: Other ponds in BBR Phases 1-2 | C8: [TBD] | D8: Unknown | E8: Residents described four in 2024 | F8: Missing storage | G8: SDP inventory | H8: Mechanical
A9: 5 | B9: Design storm | C9: [TBD] mm/h for [TBD]-year event | D9: Assumed | E9: MSMA 2 curves (may be outdated) | F9: Storage need under- or over-stated | G9: Updated local rainfall data | H9: Mechanical
A10: 6 | B10: Runoff coefficient | C10: [TBD] | D10: Assumed | E10: Land-cover table | F10: Runoff mis-estimated | G10: Site data | H10: Mechanical
A11: 7 | B11: Terrain vertical error | C11: About 1.1 m in built-up areas | D11: Sourced | E11: Developer-reported for FABDEM (Fathom) | F11: Low-lying zones misranked | G11: LiDAR (JUPEM or SDP) | H11: Mechanical
A12: 8 | B12: Drain capacity and pump rates | C12: Not modelled | D12: Unknown | E12: No public data | F12: Local failures missed | G12: Drain and pump inventory | H12: Mechanical
A13: 9 | B13: Catchment area (Setia Alam to BBR) | C13: [computed] | D13: Computed | E13: From elevation model (D3, M1) | F13: Contribution mis-stated | G13: Reviewed delineation | H13: Mechanical
A14: 10 | B14: Storage required | C14: [computed: low / central / high] | D14: Computed | E14: M3 | F14: Gap mis-stated | G14: Updated inputs | H14: Mechanical

Sheet Open Items
A1: Open Items and Risks
A2: Verify before submitting; manage risks every few days.
A4: # | B4: Type | C4: Item | D4: Why it matters | E4: Owner | F4: Status
A5: 1 | B5: Verify | C5: Year of the SDP managing director's 'top priority' quote (The Edge) | D5: Used on Slide 2 | E5: EE-3 Evidence & Pitch | F5: Open
A6: 2 | B6: Verify | C6: Whether the Taman Mutiara pond was completed after March 2025; date and amount of the Selangor Journal report | D6: Affects storage numbers and the story | E6: Mechanical | F6: Open
A7: 3 | B7: Verify | C7: Geographic scope of '300 unmanned ponds / 55 taken over by DID' (Klang or wider) | D7: Cited on Slide 4 | E7: EE-3 Evidence & Pitch | F7: Open
A8: 4 | B8: Verify | C8: Which BBR neighbourhoods SDP actually developed (Taman Mutiara, Pekan Meru may not be SDP) | D8: Labels on all maps and slides | E8: Whole team | F8: Open
A9: 5 | B9: Verify | C9: FABDEM licence terms for a competition submission | D9: Legal use of data | E9: EE-1 Data/GIS | F9: Open
A10: 6 | B10: Verify | C10: data.gov.my licence and rate limits | D10: Advisory prototype | E10: EE-2 Dashboard | F10: Open
A11: 7 | B11: Verify | C11: Whether myPublicInfoBanjir offers any permitted access (do not scrape) | D11: Data source for alerts | E11: EE-2 Dashboard | F11: Open
A12: 8 | B12: Verify | C12: Whether the organisers set a 2-3 year implementation expectation | D12: Slide 9 wording | E12: Whole team | F12: Open
A13: 9 | B13: Verify | C13: Read remaining SDP booklet pages (1, 2, 4, 6) for more volumes | D13: Better starting numbers | E13: Mechanical | F13: Open
A14: 10 | B14: Verify | C14: Do not use KLASS RM144m or RM574.5m figures (appeared only in search summaries) | D14: Unsupported claims | E14: EE-3 Evidence & Pitch | F14: Open
A15: 11 | B15: Risk | C15: Overclaiming accuracy (terrain error is about 1 m) | D15: Credibility. Mitigation: risk bands, ledger, sensitivity chart | E15: Mechanical | F15: Open
A16: 12 | B16: Risk | C16: Sounding like we blame SDP, councils or residents | D16: Sensitivity. Mitigation: neutral language, flow paths and capacity only | E16: Whole team | F16: Open
... A23: 19 | B23: Risk | C23: Large 3D files slow the web dashboard | D23: Demo reliability. Mitigation: A6 optimisation | E23: Architecture | F23: Open
